Workbook

Sheet Form Responses
A1: Timestamp | B1: Email Address | C1: Team Name | D1: SIH Interested Category | E1: Team Leader Roll Number (Member 1) | F1: Team Leader Name (Member 1) | G1: Team Leader Year of Study (Member 1) | H1: Team Leader Department (Member 1) | I1: Team Leader Contact Number (Member 1) | J1: Team Leader College Mail ID (Member 1) | K1: Roll Number (Member 2) | L1: Student Name (Member 2) | M1: Year of Study (Member 2) | N1: Department (Member 2) | O1: Roll Number (Member 3) | P1: Student Name (Member 3) | Q1: Year of Study (Member 3) | R1: Department (Member 3) | S1: Roll Number (Member 4) | T1: Student Name (Member 4) | U1: Year of Study (Member 4) | V1: Department (Member 4) | W1: Roll Number (Member 5) | X1: Student Name (Member 5) | Y1: Year of Study (Member 5) | Z1: Department (Member 5) | AA1: Roll Number (Member 6) | AB1: Student Name (Member 6) | AC1: Year of Study (Member 6) | AD1: Department (Member 6) | AE1: Acknowledgment
A2: 46238.493 | B2: manishraghul.sj2023cse@sece.ac.in | C2: AUTOM SQUAD | D2: Hardware | E2: 23CS083 | F2: MANISH RAGHUL S J | G2: IV | H2: CSE | I2: 8220563218 | J2: manishraghul.sj2023cse@sece.ac.in | K2: 24CC005 | L2: ANGELIN SHARMELL E | M2: III | N2: CCE | O2: 25CS147 | P2: NETHRA V D | Q2: II | R2: CSE | S2: 25CS150 | T2: NIRMAL S R | U2: II | V2: CSE | W2: 25EC033 | X2: DEVANAND I | Y2: II | Z2: ECE | AA2: 25CS030 | AB2: DEEPIKA K | AC2: II | AD2: CSE | AE2: I acknowledge that all the team details provided in this form are correct and accurate to the best of my knowledge. I understand that I am responsible for ensuring the accuracy of the information submitted and accept responsibility for any errors or omissions.
A3: 46238.5 | B3: anas.f2024csbs@sece.ac.in | C3: TEAM JARVIS | D3: Hardware | E3: 25AD030 | F3: DEEPAK M S | G3: II | H3: AI & DS | I3: 9361137378 | J3: deepak.ms2025aids@sece.ac.in | K3: 24CB002 | L3: ANAS F | M3: III | N3: CSBS | O3: 25AD019 | P3: ATCHAYA E | Q3: II | R3: AI & DS | S3: 25AD031 | T3: DEEPALAKSHMI S | U3: II | V3: AI & DS | W3: 25EE059 | X3: VIJAY KARUPPUSAMY S | Y3: II | Z3: EEE | AA3: 25EE033 | AB3: NESA RAJAN R | AC3: II | AD3: EEE | AE3: I acknowledge that all the team details provided in this form are correct and accurate to the best of my knowledge. I understand that I am responsible for ensuring the accuracy of the information submitted and accept responsibility for any errors or omissions.
A4: 46238.613 | B4: nithish.s2024aids@sece.ac.in | C4: Syntax Squad | D4: Software | E4: 24AD147 | F4: Nithish S | G4: III | H4: AI & DS | I4: 9080463640 | J4: nithish.s2024aids@sece.ac.in | K4: 24AD163 | L4: PREM NARAYN N L | M4: III | N4: AI & DS | O4: 24AD134 | P4: MUKESH KANNAN T | Q4: III | R4: AI & DS | S4: 24AD168 | T4: RAGHAV V | U4: III | V4: AI & DS | W4: 24CS171 | X4: POOJA P | Y4: III | Z4: CSE | AA4: 24CS275 | AB4: ZERA SHAHADIYA S | AC4: III | AD4: CSE | AE4: I acknowledge that all the team details provided in this form are correct and accurate to the best of my knowledge. I understand that I am responsible for ensuring the accuracy of the information submitted and accept responsibility for any errors or omissions.
A5: 46238.616 | B5: vasanthraj.sm2024csbs@sece.ac.in | C5: Code Catalyst | D5: Software | E5: 24CB061 | F5: Vasanthraj S M | G5: III | H5: CSBS | I5: 8270404017 | J5: vasanthraj.sm2024csbs@sece.ac.in | K5: 24CB028 | L5: Nitin K | M5: III | N5: CSBS | O5: 24CB053 | P5: SriSuthan V P R | Q5: III | R5: CSBS | S5: 24CB016 | T5: Ilakiya K | U5: III | V5: CSBS | W5: 24CB041 | X5: Sandhya S | Y5: III | Z5: CSBS | AA5: 24AD225 | AB5: Sujitha P | AC5: III | AD5: AI & DS | AE5: I acknowledge that all the team details provided in this form are correct and accurate to the best of my knowledge. I understand that I am responsible for ensuring the accuracy of the information submitted and accept responsibility for any errors or omissions.
A6: 46238.927 | B6: vishwahari.m2025ece@sece.ac.in | C6: PHEONIX CREW | D6: Hardware | E6: 25CC060 | F6: THIVYA SRIEE S M | G6: II | H6: CCE | I6: 8072742100 | J6: thivyasriee.sm2025cce@sece.ac.in | K6: 25EC152 | L6: SHREE AKILA R | M6: II | N6: ECE | O6: 25EC161 | P6: SRINITHI M | Q6: II | R6: ECE | S6: 25EC184 | T6: VISHWA HARI M | U6: II | V6: ECE | W6: 25ME012 | X6: JEEVANIGA S B | Y6: II | Z6: MECH | AA6: 25CS201 | AB6: SANTHISH N | AC6: II | AD6: CSE | AE6: I acknowledge that all the team details provided in this form are correct and accurate to the best of my knowledge. I understand that I am responsible for ensuring the accuracy of the information submitted and accept responsibility for any errors or omissions.
A7: 46239.39 | B7: saumyajitpurakayastha.2024cse@sece.ac.in | C7: Team RBC | D7: Software | E7: 24CS218 | F7: SAUMYAJIT PURAKAYASTHA | G7: III | H7: CSE | I7: 9159156405 | J7: saumyajitpurakayastha.2024cse@sece.ac.in | K7: 24CS223 | L7: SHANKAR L | M7: III | N7: CSE | O7: 24CS270 | P7: YAAZHVENDHAN M | Q7: III | R7: CSE | S7: 25CS028 | T7: DEBADRUTI PURAKAYASTHA | U7: II | V7: CSE | W7: 24AD224 | X7: Suji G | Y7: II | Z7: AI&DS | AA7: 25CB040 | AB7: Rithish Krishna A | AC7: II | AD7: CSBS | AE7: I acknowledge that all the team details provided in this form are correct and accurate to the best of my knowledge. I understand that I am responsible for ensuring the accuracy of the information submitted and accept responsibility for any errors or omissions.
A8: 46239.567 | B8: sivavashini.s2023csbs@sece.ac.in | C8: Team Tech | D8: Software | E8: 23CB051 | F8: SIVAVASHINI S | G8: IV | H8: CSBS | I8: 9003467635 | J8: sivavashini.s2023csbs@sece.ac.in | K8: 23CB004 | L8: ANGUPRANISA U | M8: IV | N8: CSBS | O8: 23AD116 | P8: SAKTHIVEL M | Q8: IV | R8: AI & DS | S8: 23AD118 | T8: SANDHYA A | U8: IV | V8: CSBS | W8: 23CC044 | X8: SAMUVEL GIPSON S | Y8: IV | Z8: CCE | AA8: 23AD128 | AB8: SELVAMOUNIKA K | AC8: IV | AD8: AI & DS | AE8: I acknowledge that all the team details provided in this form are correct and accurate to the best of my knowledge. I understand that I am responsible for ensuring the accuracy of the information submitted and accept responsibility for any errors or omissions.
A9: 46239.617 | B9: akshaysrinivasan.2025cse@sece.ac.in | C9: IDEAFORGE | D9: Software | E9: 25CS007 | F9: AKSHAY SRINIVASAN | G9: II | H9: CSE | I9: 7873737353 | J9: akshaysrinivasan.2025cse@sece.ac.in | K9: 25CS050 | L9: ELIYAS J | M9: II | N9: CSE | O9: 25CS064 | P9: HARIHARAN S D | Q9: II | R9: CSE | S9: 25CS065 | T9: HARIKISHAN J | U9: II | V9: CSE | W9: 25CS014 | X9: ASHEENA A | Y9: II | Z9: CSE | AA9: 25CS013 | AB9: ARUN R | AC9: II | AD9: CSE | AE9: I acknowledge that all the team details provided in this form are correct and accurate to the best of my knowledge. I understand that I am responsible for ensuring the accuracy of the information submitted and accept responsibility for any errors or omissions.
A10: 46239.628 | B10: sridharsan.s2025csbs@sece.ac.in | C10: TEAM AURA | D10: Software | E10: 25CB054 | F10: SRI DHARSAN S | G10: II | H10: CSBS | I10: 6369201441 | J10: sridharsan.s2025csbs@sece.ac.in | K10: 25CB001 | L10: AKSHAYA VA | M10: II | N10: CSBS | O10: 25CB035 | P10: PRANAV M | Q10: II | R10: CSBS | S10: 25CB021 | T10: JOSHITHAA SK | U10: II | V10: CSBS | W10: 25EC084 | X10: LAKSHNA S | Y10: II | Z10: ECE | AA10: LATERAL | AB10: MONIKKA SRI BG | AC10: II | AD10: ECE | AE10: I acknowledge that all the team details provided in this form are correct and accurate to the best of my knowledge. I understand that I am responsible for ensuring the accuracy of the information submitted and accept responsibility for any errors or omissions.
A11: 46239.632 | B11: rithimalya.pk2025cse@sece.ac.in | C11: Spark squad | D11: Hardware | E11: 25CS186 | F11: V Rithika | G11: II | H11: CSE | I11: +91 76048 58266 | J11: rithika.v2025cse@sece.ac.in | K11: 25CS187 | L11: Rithi Malya P K | M11: II | N11: CSE | O11: 25AD116 | P11: Mahanth P | Q11: II | R11: AI & DS | S11: 25AD109 | T11: Kunal B | U11: II | V11: AI & DS | W11: 25AD115 | X11: Mahanithi M.A | Y11: II | Z11: AI & DS | AA11: 25AM011 | AB11: Bavishyaa | AC11: II | AD11: CSE (AIML) | AE11: I acknowledge that all the team details provided in this form are correct and accurate to the best of my knowledge. I understand that I am responsible for ensuring the accuracy of the information submitted and accept responsibility for any errors or omissions.
A12: 46239.651 | B12: parthivsriram.b2025cse@sece.ac.in | C12: Tech Vortex | D12: Software | E12: 25CS174 | F12: PRAVEEN.G | G12: II | H12: CSE | I12: 8680008969 | J12: praveen.g2025cse@sece.ac.in | K12: 25CS164 | L12: PARTHIV SRIRAM B | M12: II | N12: CSE | O12: 25CS179 | P12: RAGAV CS | Q12: II | R12: CSE | S12: 25CS185 | T12: RITHIKA P | U12: II | V12: CSE | W12: 25CS165 | X12: PAVITHRA V | Y12: II | Z12: CSE | AA12: 25EC056 | AB12: HARSHAN GK | AC12: II | AD12: ECE | AE12: I acknowledge that all the team details provided in this form are correct and accurate to the best of my knowledge. I understand that I am responsible for ensuring the accuracy of the information submitted and accept responsibility for any errors or omissions.
A13: 46239.709 | B13: devakash.kl2025aids@sece.ac.in | C13: HEXA ELITE | D13: Software | E13: 25AD034 | F13: DEV AKASH K L | G13: II | H13: AI & DS | I13: 9025116542 | J13: devakash.kl2025aids@sece.ac.in | K13: 25AD021 | L13: AZEEM M S | M13: II | N13: AI & DS | O13: 25AD024 | P13: BHARATH KUMAR S | Q13: II | R13: AI & DS | S13: 25EC008 | T13: ADLIEN G A | U13: II | V13: ECE | W13: 25EC057 | X13: HARSHINI N | Y13: II | Z13: ECE | AA13: 25CC004 | AB13: DEVADHARUN R | AC13: II | AD13: CCE | AE13: I acknowledge that all the team details provided in this form are correct and accurate to the best of my knowledge. I understand that I am responsible for ensuring the accuracy of the information submitted and accept responsibility for any errors or omissions.
A14: 46239.721 | B14: ragu.r2025eee@sece.ac.in | C14: Tech X | D14: Hardware | E14: 25EE007 | F14: DHANYASHREE SJ | G14: II | H14: EEE | I14: 82203 37742 | J14: dhanyashree.sj2025eee@sece.ac.in | K14: 25EE041 | L14: RAGU R | M14: II | N14: EEE | O14: 25EE042 | P14: RITHUN K | Q14: II | R14: EEE | S14: 25CS046 | T14: DIVYA DHARSHINI A | U14: II | V14: CSE | W14: 25CS022 | X14: BHAVADHARANI R | Y14: II | Z14: CSE | AA14: 25AD220 | AB14: TARUN T | AC14: II | AD14: AI & DS | AE14: I acknowledge that all the team details provided in this form are correct and accurate to the best of my knowledge. I understand that I am responsible for ensuring the accuracy of the information submitted and accept responsibility for any errors or omissions.
A15: 46239.725 | B15: niketha.m2025ece@sece.ac.in | C15: VISION VORTEX | D15: Hardware | E15: 25EC117 | F15: NIKETHA M | G15: II | H15: ECE | I15: 8667452377 | J15: niketha.m2025ece@sece.ac.in | K15: 25EC093 | L15: MANORANJITHAM S | M15: II | N15: ECE | O15: 25EC071 | P15: KAVI KEERTHANA L | Q15: II | R15: ECE | S15: 25EC094 | T15: MARIRAJ V | U15: II | V15: ECE | W15: 25EC070 | X15: KARTHIKEYAN S | Y15: II | Z15: ECE | AA15: 25EE034 | AB15: NIRANJNA S | AC15: II | AD15: EEE | AE15: I acknowledge that all the team details provided in this form are correct and accurate to the best of my knowledge. I understand that I am responsible for ensuring the accuracy of the information submitted and accept responsibility for any errors or omissions.
A16: 46239.751 | B16: varun.s2025aids@sece.ac.in | C16: Tech veda | D16: Software | E16: 25AD222 | F16: Thamarai Selvan .G | G16: II | H16: AI & DS | I16: 9345054448 | J16: thamaraiselvan.g2025aids@sece.ac.in | K16: 25AD235 | L16: Varun .S | M16: II | N16: AI & DS | O16: 25AD250 | P16: Yakshini.M | Q16: II | R16: AI & DS | S16: 24AD241 | T16: Vikram J | U16: II | V16: AI & DS | W16: 25CC050 | X16: Shafrin.M | Y16: II | Z16: CCE | AA16: 25CC051 | AB16: Shalini.M | AC16: II | AD16: CCE | AE16: I acknowledge that all the team details provided in this form are correct and accurate to the best of my knowledge. I understand that I am responsible for ensuring the accuracy of the information submitted and accept responsibility for any errors or omissions.
A17: 46239.766 | B17: yogash.sa2024it@sece.ac.in | C17: INFINITY BLOOMS | D17: Software | E17: 24IT015 | F17: HARISWARAN M | G17: III | H17: IT | I17: 9786881013 | J17: hariswaran.m2024it@sece.ac.in | K17: 24IT062 | L17: YOGASH S A | M17: III | N17: IT | O17: 24IT501 | P17: KAVIYAA R | Q17: III | R17: IT | S17: 24CS187 | T17: RAMYA M | U17: III | V17: CSE | W17: 24IT056 | X17: SOWMIYA B | Y17: III | Z17: IT | AA17: 24EE010 | AB17: DIVITH S | AC17: III | AD17: EEE | AE17: I acknowledge that all the team details provided in this form are correct and accurate to the best of my knowledge. I understand that I am responsible for ensuring the accuracy of the information submitted and accept responsibility for any errors or omissions.
A18: 46239.796 | B18: sowmya.n2025aids@sece.ac.in | C18: Beyond binary | D18: Hardware | E18: 25AD204 | F18: SOWMYA N | G18: II | H18: AI & DS | I18: 8754696646 | J18: sowmya.n2025aids@sece.ac.in | K18: 25AD218 | L18: TAMILKAVI G | M18: II | N18: AI & DS | O18: 25AD182 | P18: SANGAVI R | Q18: II | R18: AI & DS | S18: 25EC089 | T18: MADHUMITRAA KT | U18: II | V18: ECE | W18: 25AD207 | X18: SRINIDHI K | Y18: II | Z18: AI & DS | AA18: 25AD230 | AB18: VAISHNAVI P | AC18: II | AD18: AI & DS | AE18: I acknowledge that all the team details provided in this form are correct and accurate to the best of my knowledge. I understand that I am responsible for ensuring the accuracy of the information submitted and accept responsibility for any errors or omissions.
A19: 46239.798 | B19: monish.pp2025cse@sece.ac.in | C19: Hack Club | D19: Hardware | E19: 25CS136 | F19: Monish PP | G19: II | H19: CSE | I19: 8870936233 | J19: monish.pp2025cse@sece.ac.in | K19: 25CS141 | L19: NandaKumar K | M19: II | N19: CSE | O19: 25CS130 | P19: Mohamed Faaiz A | Q19: II | R19: CSE | S19: 25CS135 | T19: Mohith M | U19: II | V19: CSE | W19: 25CB041 | X19: Ritika L | Y19: II | Z19: CSBS | AA19: 25IT043 | AB19: Rithiga RT | AC19: II | AD19: IT | AE19: I acknowledge that all the team details provided in this form are correct and accurate to the best of my knowledge. I understand that I am responsible for ensuring the accuracy of the information submitted and accept responsibility for any errors or omissions.
A20: 46239.824 | B20: sudharshan.s2024csbs@sece.ac.in | C20: Unity Minds | D20: Software | E20: 24CB011 | F20: Dharanidharan T | G20: III | H20: CSBS | I20: 6374788857 | J20: dharanidharan.t2024csbs@sece.ac.in | K20: 24CB056 | L20: Sudharshan S | M20: III | N20: CSBS | O20: 24CB063 | P20: Vishwa K | Q20: III | R20: CSBS | S20: 24CB033 | T20: Pratheeka A C | U20: III | V20: CSBS | W20: 24CB045 | X20: Shanjana R S | Y20: III | Z20: CSBS | AA20: 24AM026 | AB20: GOKUL M | AC20: III | AD20: CSE (AIML) | AE20: I acknowledge that all the team details provided in this form are correct and accurate to the best of my knowledge. I understand that I am responsible for ensuring the accuracy of the information submitted and accept responsibility for any errors or omissions.
A21: 46239.865 | B21: mathanghi.rr2025cse@sece.ac.in | C21: HACKMATES | D21: Software | E21: 25CS125 | F21: Mathanghi RR | G21: II | H21: CSE | I21: 9384481724 | J21: mathanghi.rr2025cse@sece.ac.in | K21: 25CS101 | L21: Kavishka PS | M21: II | N21: CSE | O21: 25CS071 | P21: Haritha P | Q21: II | R21: CSE | S21: 25CS097 | T21: Karthikeyan N | U21: II | V21: CSE | W21: 23CS301 | X21: Ajalesh B | Y21: IV | Z21: CSE | AA21: 25AM034 | AB21: Gowdham V | AC21: II | AD21: CSE (AIML) | AE21: I acknowledge that all the team details provided in this form are correct and accurate to the best of my knowledge. I understand that I am responsible for ensuring the accuracy of the information submitted and accept responsibility for any errors or omissions.
A22: 46239.88 | B22: dineshkumar.s2024eee@sece.ac.in | C22: Celestials | D22: Hardware | E22: 24EE009 | F22: Dinesh Kumar S | G22: III | H22: EEE | I22: 8870904088 | J22: dineshkumar.s2024eee@sece.ac.in | K22: 24CS087 | L22: Ilamsaravanbalaji Pa | M22: III | N22: CSE | O22: 24CYS058 | P22: Swetha B | Q22: III | R22: CSE (CYS) | S22: 24EE016 | T22: Harshavardhan N | U22: III | V22: EEE | W22: 24EE065 | X22: Yuvanesh C B | Y22: III | Z22: EEE | AA22: 25EE005 | AB22: Bhoosith P | AC22: II | AD22: EEE | AE22: I acknowledge that all the team details provided in this form are correct and accurate to the best of my knowledge. I understand that I am responsible for ensuring the accuracy of the information submitted and accept responsibility for any errors or omissions.
A23: 46239.896 | B23: kavimagi.s2025ece@sece.ac.in | C23: Hack Nova | D23: Hardware | E23: 25EC072 | F23: KAVIMAGI.S | G23: II | H23: ECE | I23: 8610081832 | J23: kavimagi.s2025ece@sece.ac.in | K23: 25EC004 | L23: ABI NANDITA SV | M23: II | N23: ECE | O23: 25EC121 | P23: NISHANTHI M | Q23: II | R23: ECE | S23: 25CB057 | T23: THARUNICA GJ | U23: II | V23: CSBS | W23: 25CB056 | X23: SUJITHA GAYATHRI G | Y23: II | Z23: CSBS | AA23: 25AD092 | AB23: KARPAGA PAVITHRA P | AC23: II | AD23: AI & DS | AE23: I acknowledge that all the team details provided in this form are correct and accurate to the best of my knowledge. I understand that I am responsible for ensuring the accuracy of the information submitted and accept responsibility for any errors or omissions.
A24: 46239.903 | B24: dharrshini.s2025ece@sece.ac.in | C24: HYPERNOVA | D24: Hardware | E24: 25EC039 | F24: DHARRSHINI S | G24: II | H24: ECE | I24: 8248439655 | J24: dharrshini.s2025ece@sece.ac.in | K24: 25IT004 | L24: ANU VARSHINI N | M24: II | N24: IT | O24: 25CC054 | P24: SOWBARNIKA P | Q24: II | R24: CCE | S24: 25EC037 | T24: DHARANESH S | U24: II | V24: ECE | W24: 25EC047 | X24: GOUSEEKAN V S | Y24: II | Z24: ECE | AA24: 25EC055 | AB24: HARISH KISHORE M | AC24: II | AD24: ECE | AE24: I acknowledge that all the team details provided in this form are correct and accurate to the best of my knowledge. I understand that I am responsible for ensuring the accuracy of the information submitted and accept responsibility for any errors or omissions.
A25: 46239.912 | B25: moniga.j2025ece@sece.ac.in | C25: HACK HORIZON | D25: Hardware | E25: 25EC111 | F25: NAKSHATHRA M | G25: II | H25: ECE | I25: 8148893300 | J25: nakshathra.m2025@sece.ac.in | K25: 25EC104 | L25: MONIGA J | M25: II | N25: ECE | O25: 25EC077 | P25: KAVIYA M | Q25: II | R25: ECE | S25: 25AM017 | T25: DHANUSHRI J | U25: II | V25: CSE (AIML) | W25: 25CS054 | X25: GOBIKASREE K T | Y25: II | Z25: CSE | AA25: 25AD100 | AB25: KAVYA R | AC25: II | AD25: AI & DS | AE25: I acknowledge that all the team details provided in this form are correct and accurate to the best of my knowledge. I understand that I am responsible for ensuring the accuracy of the information submitted and accept responsibility for any errors or omissions.
A26: 46239.917 | B26: divakar.g2024lcse@sece.ac.in | C26: CODEVORTEX | D26: Software | E26: 24CS215 | F26: SARAVANAPERUMAL.M | G26: III | H26: CSE | I26: 73971 48323 | J26: saravanaperumal.m2024cse@sece.ac.in | K26: 24CS305 | L26: DIVAKAR.G | M26: III | N26: CSE | O26: 24CS307 | P26: HEMALATHA.R | Q26: III | R26: CSE | S26: 24CC301 | T26: DHINESH KUMAR.S | U26: III | V26: CCE | W26: 24CC028 | X26: MATHIMOZHI.J | Y26: III | Z26: CCE | AA26: 24CS306 | AB26: GOKUL.S | AC26: III | AD26: CSE | AE26: I acknowledge that all the team details provided in this form are correct and accurate to the best of my knowledge. I understand that I am responsible for ensuring the accuracy of the information submitted and accept responsibility for any errors or omissions.
A27: 46239.924 | B27: meiharishgokul.s2024cce@sece.ac.in | C27: Quantables | D27: Software | E27: 24CC029 | F27: MEI HARISH GOKUL S | G27: III | H27: CCE | I27: 7871736516 | J27: meiharishgokul.s2024cce@sece.ac.in | K27: 24CC030 | L27: MOHAMED JESEEM T | M27: III | N27: CCE | O27: 24CC055 | P27: SUGIRTHAN S | Q27: III | R27: CCE | S27: 24CC056 | T27: SURUTHI V | U27: III | V27: CCE | W27: 24CS314 | X27: MURUGANANDHAM A | Y27: III | Z27: CSE | AA27: 24CB007 | AB27: DEEPAK E | AC27: III | AD27: CSBS | AE27: I acknowledge that all the team details provided in this form are correct and accurate to the best of my knowledge. I understand that I am responsible for ensuring the accuracy of the information submitted and accept responsibility for any errors or omissions.
A28: 46239.932 | B28: kirithika.sk2024cse@sece.ac.in | C28: Teamforge | D28: Software | E28: .24cs118 | F28: .Niranjoan KS | G28: III | H28: CSE | I28: 9344945496 | J28: niranjoan.ks2024cse@sece.ac.in | K28: 24cs118 | L28: Kirithika SK | M28: III | N28: CSE | O28: 24CS113 | P28: Kavya K | Q28: III | R28: CSE | S28: 24CS045 | T28: Deepika T | U28: III | V28: CSE | W28: 24CS199 | X28: Roobak S | Y28: III | Z28: CSE | AA28: 24CS203 - | AB28: Sachit K | AC28: III | AD28: CSE | AE28: I acknowledge that all the team details provided in this form are correct and accurate to the best of my knowledge. I understand that I am responsible for ensuring the accuracy of the information submitted and accept responsibility for any errors or omissions.
A29: 46239.933 | B29: anushya.m2025aiml@sece.ac.in | C29: HackHolics | D29: Software | E29: 25CB055 | F29: SRIRAMPRANAV N | G29: II | H29: CSBS | I29: 70921 15337 | J29: srirampranav.n2025csbs@sece.ac.in | K29: 25CB005 | L29: BRITE SAMSEKAR A | M29: II | N29: CSBS | O29: 25CB048 | P29: Shashvanth | Q29: II | R29: CSBS | S29: 25AM006 | T29: ANUSHYA M | U29: II | V29: CSE (AIML) | W29: 25AM012 | X29: BHAVANASHRI M | Y29: II | Z29: CSE (AIML) | AA29: 25AM062 | AB29: MALINI D | AC29: II | AD29: CSE (AIML) | AE29: I acknowledge that all the team details provided in this form are correct and accurate to the best of my knowledge. I understand that I am responsible for ensuring the accuracy of the information submitted and accept responsibility for any errors or omissions.
A30: 46239.939 | B30: kamalikasree.s2025ece@sece.ac.in | C30: KAMALIKA SREE S | D30: Hardware | E30: 25EC065 | F30: KAMALIKA SREE S | G30: II | H30: ECE | I30: 7550248012 | J30: kamalikasree.s2025ece@sece.ac.in | K30: 25EC079 | L30: KAVYASREE B | M30: II | N30: ECE | O30: 25EC085 | P30: LAVANYA SHRI M | Q30: II | R30: ECE | S30: 25EC068 | T30: KANISHKA S | U30: II | V30: ECE | W30: 25AD203 | X30: SIVANANDHAM S | Y30: II | Z30: AI & DS | AA30: 25AD134 | AB30: NIRANJAN R | AC30: II | AD30: AI & DS | AE30: I acknowledge that all the team details provided in this form are correct and accurate to the best of my knowledge. I understand that I am responsible for ensuring the accuracy of the information submitted and accept responsibility for any errors or omissions.
A31: 46239.949 | B31: mohansudhandhiram.m2025ece@sece.ac.in | C31: MOHAN SUDHANDHIRAM M | D31: Hardware | E31: 25EC101 | F31: MOHAN SUDHANDHIRAM M | G31: II | H31: ECE | I31: 7871391706 | J31: mohansudhandhiram.m2025ece@sece.ac.in | K31: 25EC082 | L31: KUMAAR S | M31: II | N31: ECE | O31: 25EC116 | P31: NAVEEN PRASATH E | Q31: II | R31: ECE | S31: 25EC113 | T31: NANDHITHA B | U31: II | V31: ECE | W31: 25CS143 | X31: NANDHANA B | Y31: II | Z31: CSE | AA31: 25EC107 | AB31: MUKUNDA KRISHNA M | AC31: II | AD31: ECE | AE31: I acknowledge that all the team details provided in this form are correct and accurate to the best of my knowledge. I understand that I am responsible for ensuring the accuracy of the information submitted and accept responsibility for any errors or omissions.
A32: 46239.949 | B32: lakkeytha.s2025cse@sece.ac.in | C32: ALPHA INNOVATORS | D32: Software | E32: 25CS102 | F32: KAVIYA SRI A | G32: II | H32: CSE | I32: 8248914818 | J32: kaviyasri.a2025cse@sece.ac.in | K32: 25CS094 | L32: KARNIKA P A | M32: II | N32: CSE | O32: 25CS111 | P32: LAKKEYTHA S | Q32: II | R32: CSE | S32: 25CS112 | T32: LAKSHA S | U32: II | V32: CSE | W32: 25CS109 | X32: KOWSHIKA K | Y32: II | Z32: CSE | AA32: 25EC060 | AB32: ISWARYALAKSHMI R | AC32: II | AD32: ECE | AE32: I acknowledge that all the team details provided in this form are correct and accurate to the best of my knowledge. I understand that I am responsible for ensuring the accuracy of the information submitted and accept responsibility for any errors or omissions.
A33: 46239.968 | B33: sanjanaa.sr2025ece@sece.ac.in | C33: FORGEX | D33: Hardware | E33: 25EC141 | F33: SANJANAA S R | G33: II | H33: ECE | I33: 6381417054 | J33: sanjanaa.sr2025ece@sece.ac.in | K33: 25EC162 | L33: SRIRAM G | M33: II | N33: ECE | O33: 25EC185 | P33: VISHWA S | Q33: II | R33: ECE | S33: 25AD184 | T33: SANTHOSH KUMAR P | U33: II | V33: AI & DS | W33: 25AD188 | X33: SASMITHA R | Y33: II | Z33: AI & DS | AA33: 25EC130 | AB33: PRISCILLA D | AC33: II | AD33: ECE | AE33: I acknowledge that all the team details provided in this form are correct and accurate to the best of my knowledge. I understand that I am responsible for ensuring the accuracy of the information submitted and accept responsibility for any errors or omissions.
A34: 46239.969 | B34: manishbasnet.2024cse@sece.ac.in | C34: PROJECT POSSIBLE | D34: Software | E34: 24CS129 | F34: MANISH BASNET | G34: III | H34: CSE | I34: 7342718702 | J34: manishbasnet.2024cse@sece.ac.in | K34: 24CS025 | L34: ASHOK TAMATA | M34: III | N34: CSE | O34: 24CS015 | P34: AMAN KARN | Q34: III | R34: CSE | S34: 24CS029 | T34: BARANEETHARAN | U34: III | V34: CSE | W34: 24CS002 | X34: AASTHA GUPTA | Y34: III | Z34: CSE | AA34: 24CS044 | AB34: Deepika B | AC34: III | AD34: CSE | AE34: I acknowledge that all the team details provided in this form are correct and accurate to the best of my knowledge. I understand that I am responsible for ensuring the accuracy of the information submitted and accept responsibility for any errors or omissions.
A35: 46239.981 | B35: kavin.ssg2025ece@sece.ac.in | C35: AQUAVISION | D35: Hardware | E35: 25EC074 | F35: Kavin S S G | G35: II | H35: ECE | I35: 8778893145 | J35: Kavin.ssg2025ece@sece.ac.in | K35: 25EC003 | L35: ABHISHEK C | M35: II | N35: ECE | O35: 25EC073 | P35: KAVIN G S | Q35: II | R35: ECE | S35: 25EC069 | T35: KARTHEGAEYEN K | U35: II | V35: ECE | W35: 25AD073 | X35: INFANT CELSIYA T | Y35: II | Z35: AI & DS | AA35: 25AM097 | AB35: SHREE VARSHINI L | AC35: II | AD35: CSE (AIML) | AE35: I acknowledge that all the team details provided in this form are correct and accurate to the best of my knowledge. I understand that I am responsible for ensuring the accuracy of the information submitted and accept responsibility for any errors or omissions.
A36: 46239.983 | B36: subhamkumarbehera.2024ece@sece.ac.in | C36: SUBHAM KUMAR BEHERA | D36: Hardware | E36: 24EC162 | F36: SUBHAM KUMAR BEHERA | G36: III | H36: ECE | I36: 8778609310 | J36: subhamkumarbehera.2024ece@sece.ac.in | K36: 24EC156 | L36: Sridharan S | M36: III | N36: ECE | O36: 24EC155 | P36: Sridhar E | Q36: III | R36: ECE | S36: 24EC302 | T36: Dharaneesh M | U36: III | V36: ECE | W36: 24AD011 | X36: Ahamed Atheep K | Y36: III | Z36: AI & DS | AA36: 24AD130 | AB36: Monika S | AC36: III | AD36: AI & DS | AE36: I acknowledge that all the team details provided in this form are correct and accurate to the best of my knowledge. I understand that I am responsible for ensuring the accuracy of the information submitted and accept responsibility for any errors or omissions.
A37: 46240.358 | B37: suppriyaa.t2025aids@sece.ac.in | C37: TRIFID CODERS | D37: Software | E37: 24AD187 | F37: SANJAY VIKAS R | G37: III | H37: AI & DS | I37: 9361006457 | J37: sanjayvikas.r2024aids@sece.ac.in | K37: 25AD212 | L37: SUPPRIYAA T | M37: II | N37: AI & DS | O37: 25EC163 | P37: SRITIKA | Q37: II | R37: ECE | S37: 24AD304 | T37: KIRUBA SANKAR | U37: III | V37: AI & DS | W37: 25EC160 | X37: SRI HARI VARSHINI | Y37: II | Z37: ECE | AA37: Lateral entry | AB37: RAGAV AANANTH S K | AC37: II | AD37: AI & DS | AE37: I acknowledge that all the team details provided in this form are correct and accurate to the best of my knowledge. I understand that I am responsible for ensuring the accuracy of the information submitted and accept responsibility for any errors or omissions.
A38: 46240.396 | B38: hariharan.b2025it@sece.ac.in | C38: CRIMSON GUARDIANS | D38: Software | E38: 25IT018 | F38: HARIHARAN B | G38: II | H38: IT | I38: 6385343034 | J38: hariharan.b2025it@sece.ac.in | K38: 25AM049 | L38: KARTHIKA DEVI M | M38: II | N38: CSE (AIML) | O38: 25IT002 | P38: ALTRINE JONES F | Q38: II | R38: IT | S38: 25AM048 | T38: KANIMOZHI U | U38: II | V38: CSE (AIML) | W38: 25IT305 | X38: Surya V | Y38: II | Z38: CSE | AA38: 25IT017 | AB38: GOPALAKRISHNAN P | AC38: II | AD38: IT | AE38: I acknowledge that all the team details provided in this form are correct and accurate to the best of my knowledge. I understand that I am responsible for ensuring the accuracy of the information submitted and accept responsibility for any errors or omissions.
A39: 46240.402 | B39: mohamedasif.i2024it@sece.ac.in | C39: Brogrammers | D39: Software | E39: 24IT051 | F39: SHARUKHESH S | G39: III | H39: IT | I39: 8110875768 | J39: sharukhesh.s2024it@sece.ac.in | K39: 24IT028 | L39: MOHAMED ASIF I | M39: III | N39: IT | O39: 24IT027 | P39: MOGANAVASUDEV P | Q39: III | R39: IT | S39: 24IT058 | T39: SUWETHA B | U39: III | V39: IT | W39: 24CC001 | X39: ADITHYAN R | Y39: III | Z39: CCE | AA39: 24CC039 | AB39: PRANAW SOMESH R | AC39: III | AD39: CCE | AE39: I acknowledge that all the team details provided in this form are correct and accurate to the best of my knowledge. I understand that I am responsible for ensuring the accuracy of the information submitted and accept responsibility for any errors or omissions.
A40: 46240.408 | B40: jayasri.b2025laiml@sece.ac.in | C40: SyncverseX | D40: Software | E40: 25aiml301 | F40: JAYASRI.B | G40: II | H40: CSE (AIML) | I40: 9629815118 | J40: jayasri.b2025laiml@sece.ac.in | K40: 25aiml302 | L40: SRUTHIMITHRA.S | M40: II | N40: CSE (AIML) | O40: 25IT301 | P40: DEVESH.N | Q40: II | R40: IT | S40: IC26BTecL0081 | T40: Kowshigan.S | U40: II | V40: AI & DS | W40: IC26BTecL0035 | Y40: II | Z40: CSE (CYS) | AA40: IC26BTecL0068 | AB40: Visnu sivam A | AC40: II | AD40: IT | AE40: I acknowledge that all the team details provided in this form are correct and accurate to the best of my knowledge. I understand that I am responsible for ensuring the accuracy of the information submitted and accept responsibility for any errors or omissions.
...

Sheet Consolidated
B2: Department | C2: Students Count
C3: II Year | D3: III Year | E3: IV Year | F3: Dept Total
B4: AIDS | C4: =SUM( COUNTIF('Form Responses'!E:E,"25AD*"), COUNTIF('Form Responses'!K:K,"25AD*"), COUNTIF('Form Responses'!O:O,"25AD*"), COUNTIF('Form Responses'!S:S,"25AD*"), COUNTIF('Form Responses'!W:W,"25AD*"), COUNTIF('Form Responses'!AA:AA,"25AD*") ) -> 204 | D4: =SUM( COUNTIF('Form Responses'!E:E,"24AD*"), COUNTIF('Form Responses'!K:K,"24AD*"), COUNTIF('Form Responses'!O:O,"24AD*"), COUNTIF('Form Responses'!S:S,"24AD*"), COUNTIF('Form Responses'!W:W,"24AD*"), COUNTIF('Form Responses'!AA:AA,"24AD*") ) -> 141 | E4: =SUM( COUNTIF('Form Responses'!E:E,"23AD*"), COUNTIF('Form Responses'!K:K,"23AD*"), COUNTIF('Form Responses'!O:O,"23AD*"), COUNTIF('Form Responses'!S:S,"23AD*"), COUNTIF('Form Responses'!W:W,"23AD*"), COUNTIF('Form Responses'!AA:AA,"23AD*") ) -> 7 | F4: =SUM(C4:E4) -> 352
B5: AIML | C5: =SUM( COUNTIF('Form Responses'!E:E,"25AM*"), COUNTIF('Form Responses'!K:K,"25AM*"), COUNTIF('Form Responses'!O:O,"25AM*"), COUNTIF('Form Responses'!S:S,"25AM*"), COUNTIF('Form Responses'!W:W,"25AM*"), COUNTIF('Form Responses'!AA:AA,"25AM*") ) -> 100 | D5: =SUM( COUNTIF('Form Responses'!E:E,"24AM*"), COUNTIF('Form Responses'!K:K,"24AM*"), COUNTIF('Form Responses'!O:O,"24AM*"), COUNTIF('Form Responses'!S:S,"24AM*"), COUNTIF('Form Responses'!W:W,"24AM*"), COUNTIF('Form Responses'!AA:AA,"24AM*") ) -> 96 | E5: =SUM( COUNTIF('Form Responses'!E:E,"23AM*"), COUNTIF('Form Responses'!K:K,"23AM*"), COUNTIF('Form Responses'!O:O,"23AM*"), COUNTIF('Form Responses'!S:S,"23AM*"), COUNTIF('Form Responses'!W:W,"23AM*"), COUNTIF('Form Responses'!AA:AA,"23AM*") ) -> 5 | F5: =SUM(C5:E5) -> 201
B6: CSE | C6: =SUM( COUNTIF('Form Responses'!E:E,"25CS*"), COUNTIF('Form Responses'!K:K,"25CS*"), COUNTIF('Form Responses'!O:O,"25CS*"), COUNTIF('Form Responses'!S:S,"25CS*"), COUNTIF('Form Responses'!W:W,"25CS*"), COUNTIF('Form Responses'!AA:AA,"25CS*") ) -> 195 | D6: =SUM( COUNTIF('Form Responses'!E:E,"24CS*"), COUNTIF('Form Responses'!K:K,"24CS*"), COUNTIF('Form Responses'!O:O,"24CS*"), COUNTIF('Form Responses'!S:S,"24CS*"), COUNTIF('Form Responses'!W:W,"24CS*"), COUNTIF('Form Responses'!AA:AA,"24CS*") ) -> 138 | E6: =SUM( COUNTIF('Form Responses'!E:E,"23CS*"), COUNTIF('Form Responses'!K:K,"23CS*"), COUNTIF('Form Responses'!O:O,"23CS*"), COUNTIF('Form Responses'!S:S,"23CS*"), COUNTIF('Form Responses'!W:W,"23CS*"), COUNTIF('Form Responses'!AA:AA,"23CS*") ) -> 3 | F6: =SUM(C6:E6) -> 336
B7: CCE | C7: =SUM( COUNTIF('Form Responses'!E:E,"25CC*"), COUNTIF('Form Responses'!K:K,"25CC*"), COUNTIF('Form Responses'!O:O,"25CC*"), COUNTIF('Form Responses'!S:S,"25CC*"), COUNTIF('Form Responses'!W:W,"25CC*"), COUNTIF('Form Responses'!AA:AA,"25CC*") ) -> 45 | D7: =SUM( COUNTIF('Form Responses'!E:E,"24CC*"), COUNTIF('Form Responses'!K:K,"24CC*"), COUNTIF('Form Responses'!O:O,"24CC*"), COUNTIF('Form Responses'!S:S,"24CC*"), COUNTIF('Form Responses'!W:W,"24CC*"), COUNTIF('Form Responses'!AA:AA,"24CC*") ) -> 33 | E7: =SUM( COUNTIF('Form Responses'!E:E,"23CC*"), COUNTIF('Form Responses'!K:K,"23CC*"), COUNTIF('Form Responses'!O:O,"23CC*"), COUNTIF('Form Responses'!S:S,"23CC*"), COUNTIF('Form Responses'!W:W,"23CC*"), COUNTIF('Form Responses'!AA:AA,"23CC*") ) -> 1 | F7: =SUM(C7:E7) -> 79
B8: CYS | C8: =SUM( COUNTIF('Form Responses'!E:E,"25SY*"), COUNTIF('Form Responses'!K:K,"25SY*"), COUNTIF('Form Responses'!O:O,"25SY*"), COUNTIF('Form Responses'!S:S,"25SY*"), COUNTIF('Form Responses'!W:W,"25SY*"), COUNTIF('Form Responses'!AA:AA,"25SY*") ) -> 53 | D8: =SUM( COUNTIF('Form Responses'!E:E,"24SY*"), COUNTIF('Form Responses'!K:K,"24SY*"), COUNTIF('Form Responses'!O:O,"24SY*"), COUNTIF('Form Responses'!S:S,"24SY*"), COUNTIF('Form Responses'!W:W,"24SY*"), COUNTIF('Form Responses'!AA:AA,"24SY*") ) -> 32 | E8: =SUM( COUNTIF('Form Responses'!E:E,"23SY*"), COUNTIF('Form Responses'!K:K,"23SY*"), COUNTIF('Form Responses'!O:O,"23SY*"), COUNTIF('Form Responses'!S:S,"23SY*"), COUNTIF('Form Responses'!W:W,"23SY*"), COUNTIF('Form Responses'!AA:AA,"23SY*") ) -> 0 | F8: =SUM(C8:E8) -> 85
B9: CSBS | C9: =SUM( COUNTIF('Form Responses'!E:E,"25CB*"), COUNTIF('Form Responses'!K:K,"25CB*"), COUNTIF('Form Responses'!O:O,"25CB*"), COUNTIF('Form Responses'!S:S,"25CB*"), COUNTIF('Form Responses'!W:W,"25CB*"), COUNTIF('Form Responses'!AA:AA,"25CB*") ) -> 56 | D9: =SUM( COUNTIF('Form Responses'!E:E,"24CB*"), COUNTIF('Form Responses'!K:K,"24CB*"), COUNTIF('Form Responses'!O:O,"24CB*"), COUNTIF('Form Responses'!S:S,"24CB*"), COUNTIF('Form Responses'!W:W,"24CB*"), COUNTIF('Form Responses'!AA:AA,"24CB*") ) -> 35 | E9: =SUM( COUNTIF('Form Responses'!E:E,"23CB*"), COUNTIF('Form Responses'!K:K,"23CB*"), COUNTIF('Form Responses'!O:O,"23CB*"), COUNTIF('Form Responses'!S:S,"23CB*"), COUNTIF('Form Responses'!W:W,"23CB*"), COUNTIF('Form Responses'!AA:AA,"23CB*") ) -> 3 | F9: =SUM(C9:E9) -> 94
B10: IT | C10: =SUM( COUNTIF('Form Responses'!E:E,"25IT*"), COUNTIF('Form Responses'!K:K,"25IT*"), COUNTIF('Form Responses'!O:O,"25IT*"), COUNTIF('Form Responses'!S:S,"25IT*"), COUNTIF('Form Responses'!W:W,"25IT*"), COUNTIF('Form Responses'!AA:AA,"25IT*") ) -> 62 | D10: =SUM( COUNTIF('Form Responses'!E:E,"24IT*"), COUNTIF('Form Responses'!K:K,"24IT*"), COUNTIF('Form Responses'!O:O,"24IT*"), COUNTIF('Form Responses'!S:S,"24IT*"), COUNTIF('Form Responses'!W:W,"24IT*"), COUNTIF('Form Responses'!AA:AA,"24IT*") ) -> 40 | E10: =SUM( COUNTIF('Form Responses'!E:E,"23IT*"), COUNTIF('Form Responses'!K:K,"23IT*"), COUNTIF('Form Responses'!O:O,"23IT*"), COUNTIF('Form Responses'!S:S,"23IT*"), COUNTIF('Form Responses'!W:W,"23IT*"), COUNTIF('Form Responses'!AA:AA,"23IT*") ) -> 3 | F10: =SUM(C10:E10) -> 105
B11: ECE | C11: =SUM( COUNTIF('Form Responses'!E:E,"25EC*"), COUNTIF('Form Responses'!K:K,"25EC*"), COUNTIF('Form Responses'!O:O,"25EC*"), COUNTIF('Form Responses'!S:S,"25EC*"), COUNTIF('Form Responses'!W:W,"25EC*"), COUNTIF('Form Responses'!AA:AA,"25EC*") ) -> 170 | D11: =SUM( COUNTIF('Form Responses'!E:E,"24EC*"), COUNTIF('Form Responses'!K:K,"24EC*"), COUNTIF('Form Responses'!O:O,"24EC*"), COUNTIF('Form Responses'!S:S,"24EC*"), COUNTIF('Form Responses'!W:W,"24EC*"), COUNTIF('Form Responses'!AA:AA,"24EC*") ) -> 59 | E11: =SUM( COUNTIF('Form Responses'!E:E,"23EC*"), COUNTIF('Form Responses'!K:K,"23EC*"), COUNTIF('Form Responses'!O:O,"23EC*"), COUNTIF('Form Responses'!S:S,"23EC*"), COUNTIF('Form Responses'!W:W,"23EC*"), COUNTIF('Form Responses'!AA:AA,"23EC*") ) -> 3 | F11: =SUM(C11:E11) -> 232
B12: EEE | C12: =SUM( COUNTIF('Form Responses'!E:E,"25EE*"), COUNTIF('Form Responses'!K:K,"25EE*"), COUNTIF('Form Responses'!O:O,"25EE*"), COUNTIF('Form Responses'!S:S,"25EE*"), COUNTIF('Form Responses'!W:W,"25EE*"), COUNTIF('Form Responses'!AA:AA,"25EE*") ) -> 51 | D12: =SUM( COUNTIF('Form Responses'!E:E,"24EE*"), COUNTIF('Form Responses'!K:K,"24EE*"), COUNTIF('Form Responses'!O:O,"24EE*"), COUNTIF('Form Responses'!S:S,"24EE*"), COUNTIF('Form Responses'!W:W,"24EE*"), COUNTIF('Form Responses'!AA:AA,"24EE*") ) -> 29 | E12: =SUM( COUNTIF('Form Responses'!E:E,"23EE*"), COUNTIF('Form Responses'!K:K,"23EE*"), COUNTIF('Form Responses'!O:O,"23EE*"), COUNTIF('Form Responses'!S:S,"23EE*"), COUNTIF('Form Responses'!W:W,"23EE*"), COUNTIF('Form Responses'!AA:AA,"23EE*") ) -> 0 | F12: =SUM(C12:E12) -> 80
B13: MECH | C13: =SUM( COUNTIF('Form Responses'!E:E,"25ME*"), COUNTIF('Form Responses'!K:K,"25ME*"), COUNTIF('Form Responses'!O:O,"25ME*"), COUNTIF('Form Responses'!S:S,"25ME*"), COUNTIF('Form Responses'!W:W,"25ME*"), COUNTIF('Form Responses'!AA:AA,"25ME*") ) -> 16 | D13: =SUM( COUNTIF('Form Responses'!E:E,"24ME*"), COUNTIF('Form Responses'!K:K,"24ME*"), COUNTIF('Form Responses'!O:O,"24ME*"), COUNTIF('Form Responses'!S:S,"24ME*"), COUNTIF('Form Responses'!W:W,"24ME*"), COUNTIF('Form Responses'!AA:AA,"24ME*") ) -> 8 | E13: =SUM( COUNTIF('Form Responses'!E:E,"23ME*"), COUNTIF('Form Responses'!K:K,"23ME*"), COUNTIF('Form Responses'!O:O,"23ME*"), COUNTIF('Form Responses'!S:S,"23ME*"), COUNTIF('Form Responses'!W:W,"23ME*"), COUNTIF('Form Responses'!AA:AA,"23ME*") ) -> 0 | F13: =SUM(C13:E13) -> 24
B14: Year-wise Total | C14: =SUM(C4:C13) -> 952 | D14: =SUM(D4:D13) -> 611 | E14: =SUM(E4:E13) -> 25
B15: Total Students | C15: =SUM(C14:E14) -> 1588
B16: Total Teams | C16: =COUNTA('Form Responses'!C2:C1000) -> 273

Sheet Team Details
A1: S.No | B1: Team Name | C1: Members | D1: Roll Number | E1: Name of the Student | F1: Year of Study | G1: Department | H1: Contact Number | I1: Email ID | J1: Category
A2: 1 | B2: {=INDEX('Form Responses'!$C:$C,INT((ROW()-2)/6)+2)} -> AUTOM SQUAD | C2: Team Leader | D2: {=LET( roll, CHOOSE( MOD(ROW()-2,6)+1, INDEX('Form Responses'!E:E,INT((ROW()-2)/6)+2), INDEX('Form Responses'!K:K,INT((ROW()-2)/6)+2), INDEX('Form Responses'!O:O,INT((ROW()-2)/6)+2), INDEX('Form Responses'!S:S,INT((ROW()-2)/6)+2), INDEX('Form Responses'!W:W,INT((ROW()-2)/6)+2), INDEX('Form Responses'!AA:AA,INT((ROW()-2)/6)+2) ), IF(roll="","--NA--",roll) )} -> 23CS083 | E2: {=LET( roll, CHOOSE( MOD(ROW()-2,6)+1, INDEX('Form Responses'!F:F,INT((ROW()-2)/6)+2), INDEX('Form Responses'!L:L,INT((ROW()-2)/6)+2), INDEX('Form Responses'!P:P,INT((ROW()-2)/6)+2), INDEX('Form Responses'!T:T,INT((ROW()-2)/6)+2), INDEX('Form Responses'!X:X,INT((ROW()-2)/6)+2), INDEX('Form Responses'!AB:AB,INT((ROW()-2)/6)+2) ), IF(roll="","--NA--",roll) )} -> MANISH RAGHUL S J | F2: {=LET( roll, CHOOSE( MOD(ROW()-2,6)+1, INDEX('Form Responses'!G:G,INT((ROW()-2)/6)+2), INDEX('Form Responses'!M:M,INT((ROW()-2)/6)+2), INDEX('Form Responses'!Q:Q,INT((ROW()-2)/6)+2), INDEX('Form Responses'!U:U,INT((ROW()-2)/6)+2), INDEX('Form Responses'!Y:Y,INT((ROW()-2)/6)+2), INDEX('Form Responses'!AC:AC,INT((ROW()-2)/6)+2) ), IF(roll="","--NA--",roll) )} -> IV | G2: {=LET( roll, CHOOSE( MOD(ROW()-2,6)+1, INDEX('Form Responses'!H:H,INT((ROW()-2)/6)+2), INDEX('Form Responses'!N:N,INT((ROW()-2)/6)+2), INDEX('Form Responses'!R:R,INT((ROW()-2)/6)+2), INDEX('Form Responses'!V:V,INT((ROW()-2)/6)+2), INDEX('Form Responses'!Z:Z,INT((ROW()-2)/6)+2), INDEX('Form Responses'!AD:AD,INT((ROW()-2)/6)+2) ), IF(roll="","--NA--",roll) )} -> CSE | H2: {=IF( MOD(ROW()-2,6)=0, INDEX('Form Responses'!I:I,INT((ROW()-2)/6)+2), "-- NA --" )} -> 8220563218 | I2: {=IF( MOD(ROW()-2,6)=0, INDEX('Form Responses'!J:J,INT((ROW()-2)/6)+2), "-- NA --" )} -> manishraghul.sj2023cse@sece.ac.in | J2: {=INDEX('Form Responses'!$D:$D,INT((ROW()-2)/6)+2)} -> Hardware
A3: 2 | C3: Member 2 | D3: {=LET( roll, CHOOSE( MOD(ROW()-2,6)+1, INDEX('Form Responses'!E:E,INT((ROW()-2)/6)+2), INDEX('Form Responses'!K:K,INT((ROW()-2)/6)+2), INDEX('Form Responses'!O:O,INT((ROW()-2)/6)+2), INDEX('Form Responses'!S:S,INT((ROW()-2)/6)+2), INDEX('Form Responses'!W:W,INT((ROW()-2)/6)+2), INDEX('Form Responses'!AA:AA,INT((ROW()-2)/6)+2) ), IF(roll="","--NA--",roll) )} -> 24CC005 | E3: {=LET( roll, CHOOSE( MOD(ROW()-2,6)+1, INDEX('Form Responses'!F:F,INT((ROW()-2)/6)+2), INDEX('Form Responses'!L:L,INT((ROW()-2)/6)+2), INDEX('Form Responses'!P:P,INT((ROW()-2)/6)+2), INDEX('Form Responses'!T:T,INT((ROW()-2)/6)+2), INDEX('Form Responses'!X:X,INT((ROW()-2)/6)+2), INDEX('Form Responses'!AB:AB,INT((ROW()-2)/6)+2) ), IF(roll="","--NA--",roll) )} -> ANGELIN SHARMELL E | F3: {=LET( roll, CHOOSE( MOD(ROW()-2,6)+1, INDEX('Form Responses'!G:G,INT((ROW()-2)/6)+2), INDEX('Form Responses'!M:M,INT((ROW()-2)/6)+2), INDEX('Form Responses'!Q:Q,INT((ROW()-2)/6)+2), INDEX('Form Responses'!U:U,INT((ROW()-2)/6)+2), INDEX('Form Responses'!Y:Y,INT((ROW()-2)/6)+2), INDEX('Form Responses'!AC:AC,INT((ROW()-2)/6)+2) ), IF(roll="","--NA--",roll) )} -> III | G3: {=LET( roll, CHOOSE( MOD(ROW()-2,6)+1, INDEX('Form Responses'!H:H,INT((ROW()-2)/6)+2), INDEX('Form Responses'!N:N,INT((ROW()-2)/6)+2), INDEX('Form Responses'!R:R,INT((ROW()-2)/6)+2), INDEX('Form Responses'!V:V,INT((ROW()-2)/6)+2), INDEX('Form Responses'!Z:Z,INT((ROW()-2)/6)+2), INDEX('Form Responses'!AD:AD,INT((ROW()-2)/6)+2) ), IF(roll="","--NA--",roll) )} -> CCE | H3: {=IF( MOD(ROW()-2,6)=0, INDEX('Form Responses'!I:I,INT((ROW()-2)/6)+2), "-- NA --" )} -> -- NA -- | I3: {=IF( MOD(ROW()-2,6)=0, INDEX('Form Responses'!J:J,INT((ROW()-2)/6)+2), "-- NA --" )} -> -- NA --
A4: 3 | C4: Member 3 | D4: {=LET( roll, CHOOSE( MOD(ROW()-2,6)+1, INDEX('Form Responses'!E:E,INT((ROW()-2)/6)+2), INDEX('Form Responses'!K:K,INT((ROW()-2)/6)+2), INDEX('Form Responses'!O:O,INT((ROW()-2)/6)+2), INDEX('Form Responses'!S:S,INT((ROW()-2)/6)+2), INDEX('Form Responses'!W:W,INT((ROW()-2)/6)+2), INDEX('Form Responses'!AA:AA,INT((ROW()-2)/6)+2) ), IF(roll="","--NA--",roll) )} -> 25CS147 | E4: {=LET( roll, CHOOSE( MOD(ROW()-2,6)+1, INDEX('Form Responses'!F:F,INT((ROW()-2)/6)+2), INDEX('Form Responses'!L:L,INT((ROW()-2)/6)+2), INDEX('Form Responses'!P:P,INT((ROW()-2)/6)+2), INDEX('Form Responses'!T:T,INT((ROW()-2)/6)+2), INDEX('Form Responses'!X:X,INT((ROW()-2)/6)+2), INDEX('Form Responses'!AB:AB,INT((ROW()-2)/6)+2) ), IF(roll="","--NA--",roll) )} -> NETHRA V D | F4: {=LET( roll, CHOOSE( MOD(ROW()-2,6)+1, INDEX('Form Responses'!G:G,INT((ROW()-2)/6)+2), INDEX('Form Responses'!M:M,INT((ROW()-2)/6)+2), INDEX('Form Responses'!Q:Q,INT((ROW()-2)/6)+2), INDEX('Form Responses'!U:U,INT((ROW()-2)/6)+2), INDEX('Form Responses'!Y:Y,INT((ROW()-2)/6)+2), INDEX('Form Responses'!AC:AC,INT((ROW()-2)/6)+2) ), IF(roll="","--NA--",roll) )} -> II | G4: {=LET( roll, CHOOSE( MOD(ROW()-2,6)+1, INDEX('Form Responses'!H:H,INT((ROW()-2)/6)+2), INDEX('Form Responses'!N:N,INT((ROW()-2)/6)+2), INDEX('Form Responses'!R:R,INT((ROW()-2)/6)+2), INDEX('Form Responses'!V:V,INT((ROW()-2)/6)+2), INDEX('Form Responses'!Z:Z,INT((ROW()-2)/6)+2), INDEX('Form Responses'!AD:AD,INT((ROW()-2)/6)+2) ), IF(roll="","--NA--",roll) )} -> CSE | H4: {=IF( MOD(ROW()-2,6)=0, INDEX('Form Responses'!I:I,INT((ROW()-2)/6)+2), "-- NA --" )} -> -- NA -- | I4: {=IF( MOD(ROW()-2,6)=0, INDEX('Form Responses'!J:J,INT((ROW()-2)/6)+2), "-- NA --" )} -> -- NA --
A5: 4 | C5: Member 4 | D5: {=LET( roll, CHOOSE( MOD(ROW()-2,6)+1, INDEX('Form Responses'!E:E,INT((ROW()-2)/6)+2), INDEX('Form Responses'!K:K,INT((ROW()-2)/6)+2), INDEX('Form Responses'!O:O,INT((ROW()-2)/6)+2), INDEX('Form Responses'!S:S,INT((ROW()-2)/6)+2), INDEX('Form Responses'!W:W,INT((ROW()-2)/6)+2), INDEX('Form Responses'!AA:AA,INT((ROW()-2)/6)+2) ), IF(roll="","--NA--",roll) )} -> 25CS150 | E5: {=LET( roll, CHOOSE( MOD(ROW()-2,6)+1, INDEX('Form Responses'!F:F,INT((ROW()-2)/6)+2), INDEX('Form Responses'!L:L,INT((ROW()-2)/6)+2), INDEX('Form Responses'!P:P,INT((ROW()-2)/6)+2), INDEX('Form Responses'!T:T,INT((ROW()-2)/6)+2), INDEX('Form Responses'!X:X,INT((ROW()-2)/6)+2), INDEX('Form Responses'!AB:AB,INT((ROW()-2)/6)+2) ), IF(roll="","--NA--",roll) )} -> NIRMAL S R | F5: {=LET( roll, CHOOSE( MOD(ROW()-2,6)+1, INDEX('Form Responses'!G:G,INT((ROW()-2)/6)+2), INDEX('Form Responses'!M:M,INT((ROW()-2)/6)+2), INDEX('Form Responses'!Q:Q,INT((ROW()-2)/6)+2), INDEX('Form Responses'!U:U,INT((ROW()-2)/6)+2), INDEX('Form Responses'!Y:Y,INT((ROW()-2)/6)+2), INDEX('Form Responses'!AC:AC,INT((ROW()-2)/6)+2) ), IF(roll="","--NA--",roll) )} -> II | G5: {=LET( roll, CHOOSE( MOD(ROW()-2,6)+1, INDEX('Form Responses'!H:H,INT((ROW()-2)/6)+2), INDEX('Form Responses'!N:N,INT((ROW()-2)/6)+2), INDEX('Form Responses'!R:R,INT((ROW()-2)/6)+2), INDEX('Form Responses'!V:V,INT((ROW()-2)/6)+2), INDEX('Form Responses'!Z:Z,INT((ROW()-2)/6)+2), INDEX('Form Responses'!AD:AD,INT((ROW()-2)/6)+2) ), IF(roll="","--NA--",roll) )} -> CSE | H5: {=IF( MOD(ROW()-2,6)=0, INDEX('Form Responses'!I:I,INT((ROW()-2)/6)+2), "-- NA --" )} -> -- NA -- | I5: {=IF( MOD(ROW()-2,6)=0, INDEX('Form Responses'!J:J,INT((ROW()-2)/6)+2), "-- NA --" )} -> -- NA --
A6: 5 | C6: Member 5 | D6: {=LET( roll, CHOOSE( MOD(ROW()-2,6)+1, INDEX('Form Responses'!E:E,INT((ROW()-2)/6)+2), INDEX('Form Responses'!K:K,INT((ROW()-2)/6)+2), INDEX('Form Responses'!O:O,INT((ROW()-2)/6)+2), INDEX('Form Responses'!S:S,INT((ROW()-2)/6)+2), INDEX('Form Responses'!W:W,INT((ROW()-2)/6)+2), INDEX('Form Responses'!AA:AA,INT((ROW()-2)/6)+2) ), IF(roll="","--NA--",roll) )} -> 25EC033 | E6: {=LET( roll, CHOOSE( MOD(ROW()-2,6)+1, INDEX('Form Responses'!F:F,INT((ROW()-2)/6)+2), INDEX('Form Responses'!L:L,INT((ROW()-2)/6)+2), INDEX('Form Responses'!P:P,INT((ROW()-2)/6)+2), INDEX('Form Responses'!T:T,INT((ROW()-2)/6)+2), INDEX('Form Responses'!X:X,INT((ROW()-2)/6)+2), INDEX('Form Responses'!AB:AB,INT((ROW()-2)/6)+2) ), IF(roll="","--NA--",roll) )} -> DEVANAND I | F6: {=LET( roll, CHOOSE( MOD(ROW()-2,6)+1, INDEX('Form Responses'!G:G,INT((ROW()-2)/6)+2), INDEX('Form Responses'!M:M,INT((ROW()-2)/6)+2), INDEX('Form Responses'!Q:Q,INT((ROW()-2)/6)+2), INDEX('Form Responses'!U:U,INT((ROW()-2)/6)+2), INDEX('Form Responses'!Y:Y,INT((ROW()-2)/6)+2), INDEX('Form Responses'!AC:AC,INT((ROW()-2)/6)+2) ), IF(roll="","--NA--",roll) )} -> II | G6: {=LET( roll, CHOOSE( MOD(ROW()-2,6)+1, INDEX('Form Responses'!H:H,INT((ROW()-2)/6)+2), INDEX('Form Responses'!N:N,INT((ROW()-2)/6)+2), INDEX('Form Responses'!R:R,INT((ROW()-2)/6)+2), INDEX('Form Responses'!V:V,INT((ROW()-2)/6)+2), INDEX('Form Responses'!Z:Z,INT((ROW()-2)/6)+2), INDEX('Form Responses'!AD:AD,INT((ROW()-2)/6)+2) ), IF(roll="","--NA--",roll) )} -> ECE | H6: {=IF( MOD(ROW()-2,6)=0, INDEX('Form Responses'!I:I,INT((ROW()-2)/6)+2), "-- NA --" )} -> -- NA -- | I6: {=IF( MOD(ROW()-2,6)=0, INDEX('Form Responses'!J:J,INT((ROW()-2)/6)+2), "-- NA --" )} -> -- NA --
A7: 6 | C7: Member 6 | D7: {=LET( roll, CHOOSE( MOD(ROW()-2,6)+1, INDEX('Form Responses'!E:E,INT((ROW()-2)/6)+2), INDEX('Form Responses'!K:K,INT((ROW()-2)/6)+2), INDEX('Form Responses'!O:O,INT((ROW()-2)/6)+2), INDEX('Form Responses'!S:S,INT((ROW()-2)/6)+2), INDEX('Form Responses'!W:W,INT((ROW()-2)/6)+2), INDEX('Form Responses'!AA:AA,INT((ROW()-2)/6)+2) ), IF(roll="","--NA--",roll) )} -> 25CS030 | E7: {=LET( roll, CHOOSE( MOD(ROW()-2,6)+1, INDEX('Form Responses'!F:F,INT((ROW()-2)/6)+2), INDEX('Form Responses'!L:L,INT((ROW()-2)/6)+2), INDEX('Form Responses'!P:P,INT((ROW()-2)/6)+2), INDEX('Form Responses'!T:T,INT((ROW()-2)/6)+2), INDEX('Form Responses'!X:X,INT((ROW()-2)/6)+2), INDEX('Form Responses'!AB:AB,INT((ROW()-2)/6)+2) ), IF(roll="","--NA--",roll) )} -> DEEPIKA K | F7: {=LET( roll, CHOOSE( MOD(ROW()-2,6)+1, INDEX('Form Responses'!G:G,INT((ROW()-2)/6)+2), INDEX('Form Responses'!M:M,INT((ROW()-2)/6)+2), INDEX('Form Responses'!Q:Q,INT((ROW()-2)/6)+2), INDEX('Form Responses'!U:U,INT((ROW()-2)/6)+2), INDEX('Form Responses'!Y:Y,INT((ROW()-2)/6)+2), INDEX('Form Responses'!AC:AC,INT((ROW()-2)/6)+2) ), IF(roll="","--NA--",roll) )} -> II | G7: {=LET( roll, CHOOSE( MOD(ROW()-2,6)+1, INDEX('Form Responses'!H:H,INT((ROW()-2)/6)+2), INDEX('Form Responses'!N:N,INT((ROW()-2)/6)+2), INDEX('Form Responses'!R:R,INT((ROW()-2)/6)+2), INDEX('Form Responses'!V:V,INT((ROW()-2)/6)+2), INDEX('Form Responses'!Z:Z,INT((ROW()-2)/6)+2), INDEX('Form Responses'!AD:AD,INT((ROW()-2)/6)+2) ), IF(roll="","--NA--",roll) )} -> CSE | H7: {=IF( MOD(ROW()-2,6)=0, INDEX('Form Responses'!I:I,INT((ROW()-2)/6)+2), "-- NA --" )} -> -- NA -- | I7: {=IF( MOD(ROW()-2,6)=0, INDEX('Form Responses'!J:J,INT((ROW()-2)/6)+2), "-- NA --" )} -> -- NA --
A8: 7 | B8: {=INDEX('Form Responses'!$C:$C,INT((ROW()-2)/6)+2)} -> TEAM JARVIS | C8: Team Leader | D8: {=LET( roll, CHOOSE( MOD(ROW()-2,6)+1, INDEX('Form Responses'!E:E,INT((ROW()-2)/6)+2), INDEX('Form Responses'!K:K,INT((ROW()-2)/6)+2), INDEX('Form Responses'!O:O,INT((ROW()-2)/6)+2), INDEX('Form Responses'!S:S,INT((ROW()-2)/6)+2), INDEX('Form Responses'!W:W,INT((ROW()-2)/6)+2), INDEX('Form Responses'!AA:AA,INT((ROW()-2)/6)+2) ), IF(roll="","--NA--",roll) )} -> 25AD030 | E8: {=LET( roll, CHOOSE( MOD(ROW()-2,6)+1, INDEX('Form Responses'!F:F,INT((ROW()-2)/6)+2), INDEX('Form Responses'!L:L,INT((ROW()-2)/6)+2), INDEX('Form Responses'!P:P,INT((ROW()-2)/6)+2), INDEX('Form Responses'!T:T,INT((ROW()-2)/6)+2), INDEX('Form Responses'!X:X,INT((ROW()-2)/6)+2), INDEX('Form Responses'!AB:AB,INT((ROW()-2)/6)+2) ), IF(roll="","--NA--",roll) )} -> DEEPAK M S | F8: {=LET( roll, CHOOSE( MOD(ROW()-2,6)+1, INDEX('Form Responses'!G:G,INT((ROW()-2)/6)+2), INDEX('Form Responses'!M:M,INT((ROW()-2)/6)+2), INDEX('Form Responses'!Q:Q,INT((ROW()-2)/6)+2), INDEX('Form Responses'!U:U,INT((ROW()-2)/6)+2), INDEX('Form Responses'!Y:Y,INT((ROW()-2)/6)+2), INDEX('Form Responses'!AC:AC,INT((ROW()-2)/6)+2) ), IF(roll="","--NA--",roll) )} -> II | G8: {=LET( roll, CHOOSE( MOD(ROW()-2,6)+1, INDEX('Form Responses'!H:H,INT((ROW()-2)/6)+2), INDEX('Form Responses'!N:N,INT((ROW()-2)/6)+2), INDEX('Form Responses'!R:R,INT((ROW()-2)/6)+2), INDEX('Form Responses'!V:V,INT((ROW()-2)/6)+2), INDEX('Form Responses'!Z:Z,INT((ROW()-2)/6)+2), INDEX('Form Responses'!AD:AD,INT((ROW()-2)/6)+2) ), IF(roll="","--NA--",roll) )} -> AI & DS | H8: {=IF( MOD(ROW()-2,6)=0, INDEX('Form Responses'!I:I,INT((ROW()-2)/6)+2), "-- NA --" )} -> 9361137378 | I8: {=IF( MOD(ROW()-2,6)=0, INDEX('Form Responses'!J:J,INT((ROW()-2)/6)+2), "-- NA --" )} -> deepak.ms2025aids@sece.ac.in | J8: {=INDEX('Form Responses'!$D:$D,INT((ROW()-2)/6)+2)} -> Hardware
A9: 8 | C9: Member 2 | D9: {=LET( roll, CHOOSE( MOD(ROW()-2,6)+1, INDEX('Form Responses'!E:E,INT((ROW()-2)/6)+2), INDEX('Form Responses'!K:K,INT((ROW()-2)/6)+2), INDEX('Form Responses'!O:O,INT((ROW()-2)/6)+2), INDEX('Form Responses'!S:S,INT((ROW()-2)/6)+2), INDEX('Form Responses'!W:W,INT((ROW()-2)/6)+2), INDEX('Form Responses'!AA:AA,INT((ROW()-2)/6)+2) ), IF(roll="","--NA--",roll) )} -> 24CB002 | E9: {=LET( roll, CHOOSE( MOD(ROW()-2,6)+1, INDEX('Form Responses'!F:F,INT((ROW()-2)/6)+2), INDEX('Form Responses'!L:L,INT((ROW()-2)/6)+2), INDEX('Form Responses'!P:P,INT((ROW()-2)/6)+2), INDEX('Form Responses'!T:T,INT((ROW()-2)/6)+2), INDEX('Form Responses'!X:X,INT((ROW()-2)/6)+2), INDEX('Form Responses'!AB:AB,INT((ROW()-2)/6)+2) ), IF(roll="","--NA--",roll) )} -> ANAS F | F9: {=LET( roll, CHOOSE( MOD(ROW()-2,6)+1, INDEX('Form Responses'!G:G,INT((ROW()-2)/6)+2), INDEX('Form Responses'!M:M,INT((ROW()-2)/6)+2), INDEX('Form Responses'!Q:Q,INT((ROW()-2)/6)+2), INDEX('Form Responses'!U:U,INT((ROW()-2)/6)+2), INDEX('Form Responses'!Y:Y,INT((ROW()-2)/6)+2), INDEX('Form Responses'!AC:AC,INT((ROW()-2)/6)+2) ), IF(roll="","--NA--",roll) )} -> III | G9: {=LET( roll, CHOOSE( MOD(ROW()-2,6)+1, INDEX('Form Responses'!H:H,INT((ROW()-2)/6)+2), INDEX('Form Responses'!N:N,INT((ROW()-2)/6)+2), INDEX('Form Responses'!R:R,INT((ROW()-2)/6)+2), INDEX('Form Responses'!V:V,INT((ROW()-2)/6)+2), INDEX('Form Responses'!Z:Z,INT((ROW()-2)/6)+2), INDEX('Form Responses'!AD:AD,INT((ROW()-2)/6)+2) ), IF(roll="","--NA--",roll) )} -> CSBS | H9: {=IF( MOD(ROW()-2,6)=0, INDEX('Form Responses'!I:I,INT((ROW()-2)/6)+2), "-- NA --" )} -> -- NA -- | I9: {=IF( MOD(ROW()-2,6)=0, INDEX('Form Responses'!J:J,INT((ROW()-2)/6)+2), "-- NA --" )} -> -- NA --
A10: 9 | C10: Member 3 | D10: {=LET( roll, CHOOSE( MOD(ROW()-2,6)+1, INDEX('Form Responses'!E:E,INT((ROW()-2)/6)+2), INDEX('Form Responses'!K:K,INT((ROW()-2)/6)+2), INDEX('Form Responses'!O:O,INT((ROW()-2)/6)+2), INDEX('Form Responses'!S:S,INT((ROW()-2)/6)+2), INDEX('Form Responses'!W:W,INT((ROW()-2)/6)+2), INDEX('Form Responses'!AA:AA,INT((ROW()-2)/6)+2) ), IF(roll="","--NA--",roll) )} -> 25AD019 | E10: {=LET( roll, CHOOSE( MOD(ROW()-2,6)+1, INDEX('Form Responses'!F:F,INT((ROW()-2)/6)+2), INDEX('Form Responses'!L:L,INT((ROW()-2)/6)+2), INDEX('Form Responses'!P:P,INT((ROW()-2)/6)+2), INDEX('Form Responses'!T:T,INT((ROW()-2)/6)+2), INDEX('Form Responses'!X:X,INT((ROW()-2)/6)+2), INDEX('Form Responses'!AB:AB,INT((ROW()-2)/6)+2) ), IF(roll="","--NA--",roll) )} -> ATCHAYA E | F10: {=LET( roll, CHOOSE( MOD(ROW()-2,6)+1, INDEX('Form Responses'!G:G,INT((ROW()-2)/6)+2), INDEX('Form Responses'!M:M,INT((ROW()-2)/6)+2), INDEX('Form Responses'!Q:Q,INT((ROW()-2)/6)+2), INDEX('Form Responses'!U:U,INT((ROW()-2)/6)+2), INDEX('Form Responses'!Y:Y,INT((ROW()-2)/6)+2), INDEX('Form Responses'!AC:AC,INT((ROW()-2)/6)+2) ), IF(roll="","--NA--",roll) )} -> II | G10: {=LET( roll, CHOOSE( MOD(ROW()-2,6)+1, INDEX('Form Responses'!H:H,INT((ROW()-2)/6)+2), INDEX('Form Responses'!N:N,INT((ROW()-2)/6)+2), INDEX('Form Responses'!R:R,INT((ROW()-2)/6)+2), INDEX('Form Responses'!V:V,INT((ROW()-2)/6)+2), INDEX('Form Responses'!Z:Z,INT((ROW()-2)/6)+2), INDEX('Form Responses'!AD:AD,INT((ROW()-2)/6)+2) ), IF(roll="","--NA--",roll) )} -> AI & DS | H10: {=IF( MOD(ROW()-2,6)=0, INDEX('Form Responses'!I:I,INT((ROW()-2)/6)+2), "-- NA --" )} -> -- NA -- | I10: {=IF( MOD(ROW()-2,6)=0, INDEX('Form Responses'!J:J,INT((ROW()-2)/6)+2), "-- NA --" )} -> -- NA --
A11: 10 | C11: Member 4 | D11: {=LET( roll, CHOOSE( MOD(ROW()-2,6)+1, INDEX('Form Responses'!E:E,INT((ROW()-2)/6)+2), INDEX('Form Responses'!K:K,INT((ROW()-2)/6)+2), INDEX('Form Responses'!O:O,INT((ROW()-2)/6)+2), INDEX('Form Responses'!S:S,INT((ROW()-2)/6)+2), INDEX('Form Responses'!W:W,INT((ROW()-2)/6)+2), INDEX('Form Responses'!AA:AA,INT((ROW()-2)/6)+2) ), IF(roll="","--NA--",roll) )} -> 25AD031 | E11: {=LET( roll, CHOOSE( MOD(ROW()-2,6)+1, INDEX('Form Responses'!F:F,INT((ROW()-2)/6)+2), INDEX('Form Responses'!L:L,INT((ROW()-2)/6)+2), INDEX('Form Responses'!P:P,INT((ROW()-2)/6)+2), INDEX('Form Responses'!T:T,INT((ROW()-2)/6)+2), INDEX('Form Responses'!X:X,INT((ROW()-2)/6)+2), INDEX('Form Responses'!AB:AB,INT((ROW()-2)/6)+2) ), IF(roll="","--NA--",roll) )} -> DEEPALAKSHMI S | F11: {=LET( roll, CHOOSE( MOD(ROW()-2,6)+1, INDEX('Form Responses'!G:G,INT((ROW()-2)/6)+2), INDEX('Form Responses'!M:M,INT((ROW()-2)/6)+2), INDEX('Form Responses'!Q:Q,INT((ROW()-2)/6)+2), INDEX('Form Responses'!U:U,INT((ROW()-2)/6)+2), INDEX('Form Responses'!Y:Y,INT((ROW()-2)/6)+2), INDEX('Form Responses'!AC:AC,INT((ROW()-2)/6)+2) ), IF(roll="","--NA--",roll) )} -> II | G11: {=LET( roll, CHOOSE( MOD(ROW()-2,6)+1, INDEX('Form Responses'!H:H,INT((ROW()-2)/6)+2), INDEX('Form Responses'!N:N,INT((ROW()-2)/6)+2), INDEX('Form Responses'!R:R,INT((ROW()-2)/6)+2), INDEX('Form Responses'!V:V,INT((ROW()-2)/6)+2), INDEX('Form Responses'!Z:Z,INT((ROW()-2)/6)+2), INDEX('Form Responses'!AD:AD,INT((ROW()-2)/6)+2) ), IF(roll="","--NA--",roll) )} -> AI & DS | H11: {=IF( MOD(ROW()-2,6)=0, INDEX('Form Responses'!I:I,INT((ROW()-2)/6)+2), "-- NA --" )} -> -- NA -- | I11: {=IF( MOD(ROW()-2,6)=0, INDEX('Form Responses'!J:J,INT((ROW()-2)/6)+2), "-- NA --" )} -> -- NA --
A12: 11 | C12: Member 5 | D12: {=LET( roll, CHOOSE( MOD(ROW()-2,6)+1, INDEX('Form Responses'!E:E,INT((ROW()-2)/6)+2), INDEX('Form Responses'!K:K,INT((ROW()-2)/6)+2), INDEX('Form Responses'!O:O,INT((ROW()-2)/6)+2), INDEX('Form Responses'!S:S,INT((ROW()-2)/6)+2), INDEX('Form Responses'!W:W,INT((ROW()-2)/6)+2), INDEX('Form Responses'!AA:AA,INT((ROW()-2)/6)+2) ), IF(roll="","--NA--",roll) )} -> 25EE059 | E12: {=LET( roll, CHOOSE( MOD(ROW()-2,6)+1, INDEX('Form Responses'!F:F,INT((ROW()-2)/6)+2), INDEX('Form Responses'!L:L,INT((ROW()-2)/6)+2), INDEX('Form Responses'!P:P,INT((ROW()-2)/6)+2), INDEX('Form Responses'!T:T,INT((ROW()-2)/6)+2), INDEX('Form Responses'!X:X,INT((ROW()-2)/6)+2), INDEX('Form Responses'!AB:AB,INT((ROW()-2)/6)+2) ), IF(roll="","--NA--",roll) )} -> VIJAY KARUPPUSAMY S | F12: {=LET( roll, CHOOSE( MOD(ROW()-2,6)+1, INDEX('Form Responses'!G:G,INT((ROW()-2)/6)+2), INDEX('Form Responses'!M:M,INT((ROW()-2)/6)+2), INDEX('Form Responses'!Q:Q,INT((ROW()-2)/6)+2), INDEX('Form Responses'!U:U,INT((ROW()-2)/6)+2), INDEX('Form Responses'!Y:Y,INT((ROW()-2)/6)+2), INDEX('Form Responses'!AC:AC,INT((ROW()-2)/6)+2) ), IF(roll="","--NA--",roll) )} -> II | G12: {=LET( roll, CHOOSE( MOD(ROW()-2,6)+1, INDEX('Form Responses'!H:H,INT((ROW()-2)/6)+2), INDEX('Form Responses'!N:N,INT((ROW()-2)/6)+2), INDEX('Form Responses'!R:R,INT((ROW()-2)/6)+2), INDEX('Form Responses'!V:V,INT((ROW()-2)/6)+2), INDEX('Form Responses'!Z:Z,INT((ROW()-2)/6)+2), INDEX('Form Responses'!AD:AD,INT((ROW()-2)/6)+2) ), IF(roll="","--NA--",roll) )} -> EEE | H12: {=IF( MOD(ROW()-2,6)=0, INDEX('Form Responses'!I:I,INT((ROW()-2)/6)+2), "-- NA --" )} -> -- NA -- | I12: {=IF( MOD(ROW()-2,6)=0, INDEX('Form Responses'!J:J,INT((ROW()-2)/6)+2), "-- NA --" )} -> -- NA --
